<?xml version='1.0'?>

<robot name="robot" xmlns:xacro="http://www.ros.org/wiki/xacro">


  <xacro:include filename="$(find my_robot_simulation)/diff_drive_robot/urdf/diff_drive_robot.gazebo" />
  <xacro:include filename="$(find my_robot_simulation)/diff_drive_robot/urdf/materials.xacro" />



  <link name='base'>
    <pose>0 0 0.0 0 0 0</pose>

    <inertial>
      <mass value="20.0"/>
      <origin xyz="0.0 0 0.1" rpy=" 0 0 0"/>
      <inertia
          ixx="0.5" ixy="0" ixz="0"
          iyy="1.0" iyz="0"
          izz="0.1"
      />
    </inertial>

    <collision name='collision'>
      <geometry>
        <box size=".6 .4 .2"/>
      </geometry>
    </collision>

    <visual name='base_visual'>
      <origin xyz="0 0 0" rpy=" 0 0 0"/>
      <geometry>
        <box size=".6 .4 .2"/>
      </geometry>
      <material name="orange"/>
    </visual>


    <collision name='caster_collision_rear'>
      <origin xyz="-0.24 0 -0.08" rpy=" 0 0 0"/>
      <geometry>
        <sphere radius="0.06"/>
      </geometry>
      <surface>
        <friction>
          <ode>
            <mu>0</mu>
            <mu2>0</mu2>
            <slip1>1.0</slip1>
            <slip2>1.0</slip2>
          </ode>
        </friction>
      </surface>
    </collision>

    <visual name='caster_visual_rear'>
      <origin xyz="-0.24 0 -0.08" rpy=" 0 0 0"/>
      <geometry>
        <sphere radius="0.06"/>
      </geometry>
      <material name="white"/>
    </visual>

    <collision name='caster_collision_forward'>
      <origin xyz="0.24 0 -0.08" rpy=" 0 0 0"/>
      <geometry>
        <sphere radius="0.06"/>
      </geometry>
      <surface>
        <friction>
          <ode>
            <mu>0</mu>
            <mu2>0</mu2>
            <slip1>1.0</slip1>
            <slip2>1.0</slip2>
          </ode>
        </friction>
      </surface>
    </collision>

    <visual name='caster_visual_forward'>
      <origin xyz="0.24 0 -0.08" rpy=" 0 0 0"/>
      <geometry>
        <sphere radius="0.06"/>
      </geometry>
      <material name="white"/>
    </visual>

  </link>


  <link name="left_wheel">
    <collision name="collision">
      <origin xyz="0 0 0" rpy="0 1.5707 1.5707"/>
      <geometry>
        <cylinder radius="0.1" length="0.05"/>
      </geometry>
    </collision>
    <visual name="left_wheel_visual">
      <origin xyz="0 0 0" rpy="0 1.5707 1.5707"/>
      <geometry>
        <cylinder radius="0.1" length="0.05"/>
      </geometry>
      <material name="white"/>
    </visual>
    <inertial>
      <origin xyz="0 0 0" rpy="0 1.5707 1.5707"/>
      <mass value="5"/>
      <cylinder_inertia m="5" r="0.1" h="0.05"/>
      <inertia
        ixx="1.0" ixy="0.0" ixz="0.0"
        iyy="1.0" iyz="0.0"
        izz="1.0"/>
    </inertial>
  </link>

  <link name="right_wheel">
    <collision name="collision">
      <origin xyz="0 0 0" rpy="0 1.5707 1.5707"/>
      <geometry>
        <cylinder radius="0.1" length="0.05"/>
      </geometry>
    </collision>
    <visual name="right_wheel_visual">
      <origin xyz="0 0 0" rpy="0 1.5707 1.5707"/>
      <geometry>
        <cylinder radius="0.1" length="0.05"/>
      </geometry>
      <material name="white"/>
    </visual>
    <inertial>
      <origin xyz="0 0 0" rpy="0 1.5707 1.5707"/>
      <mass value="5"/>
      <cylinder_inertia m="5" r="0.1" h="0.05"/>
      <inertia
        ixx="1.0" ixy="0.0" ixz="0.0"
        iyy="1.0" iyz="0.0"
        izz="1.0"/>
    </inertial>
  </link>

  <link name='camera'>
    <visual name='camera_visual'>
      <origin xyz="0 0 0" rpy=" 0 0 0"/>
      <geometry>
        <box size=".05 .05 .05"/>
      </geometry>
      <material name="gray"/>
    </visual>
  </link>


  <joint type="continuous" name="left_wheel_hinge">
    <origin xyz="0.05 0.226 -0.05" rpy="0 0 0"/>
    <child link="left_wheel"/>
    <parent link="base"/>
    <axis xyz="0 1 0" rpy="0 0 0"/>
    <limit effort="100" velocity="100"/>
    <joint_properties damping="0.0" friction="0.0"/>
  </joint>

  <joint type="continuous" name="right_wheel_hinge">
    <origin xyz="0.05 -0.226 -0.05" rpy="0 0 0"/>
    <child link="right_wheel"/>
    <parent link="base"/>
    <axis xyz="0 1 0" rpy="0 0 0"/>
    <limit effort="100" velocity="100"/>
    <joint_properties damping="0.0" friction="0.0"/>
  </joint>

  <joint type="fixed" name="camera_joint">
    <origin xyz="0.3 0 0" rpy="0 0 0"/>
    <child link="camera"/>
    <parent link="base"/>
  </joint>

</robot>
